<?php

namespace Amp\Future;

use Amp\CancelledException;
use Amp\DeferredFuture;
use Amp\Future;
use Amp\TimeoutCancellation;
use PHPUnit\Framework\TestCase;
use Revolt\EventLoop;

class AwaitTest extends TestCase
{
    public function testSingleComplete(): void
    {
        self::assertSame([42], await([Future::complete(42)]));
    }

    public function testTwoComplete(): void
    {
        self::assertSame([1, 2], await([Future::complete(1), Future::complete(2)]));
    }

    public function testTwoFirstPending(): void
    {
        $deferred = new DeferredFuture;

        EventLoop::delay(0.01, fn () => $deferred->complete(1));

        self::assertSame([1 => 2, 0 => 1], await([$deferred->getFuture(), Future::complete(2)]));
    }

    public function testArrayDestructuring(): void
    {
        $deferred = new DeferredFuture;

        EventLoop::delay(0.01, fn () => $deferred->complete(1));

        [$first, $second] = await([$deferred->getFuture(), Future::complete(2)]);

        self::assertSame(1, $first);
        self::assertSame(2, $second);
    }

    public function testTwoFirstThrowing(): void
    {
        $this->expectException(\Exception::class);
        $this->expectExceptionMessage('foo');

        await([Future::error(new \Exception('foo')), Future::complete(2)]);
    }

    public function testTwoThrowingWithOneLater(): void
    {
        $this->expectException(\Exception::class);
        $this->expectExceptionMessage('foo');

        $deferred = new DeferredFuture;
        EventLoop::delay(0.1, static fn () => $deferred->error(new \Exception('bar')));

        await([Future::error(new \Exception('foo')), $deferred->getFuture()]);
    }

    public function testTwoGeneratorThrows(): void
    {
        $this->expectException(\Exception::class);
        $this->expectExceptionMessage('foo');

        await((static function () {
            yield Future::error(new \Exception('foo'));
            yield Future::complete(2);
        })());
    }

    public function testCancellation(): void
    {
        $this->expectException(CancelledException::class);
        $deferreds = \array_map(function (int $value) {
            $deferred = new DeferredFuture;
            EventLoop::delay($value / 10, fn () => $deferred->complete($value));
            return $deferred;
        }, \range(1, 3));

        await(\array_map(
            fn (DeferredFuture $deferred) => $deferred->getFuture(),
            $deferreds
        ), new TimeoutCancellation(0.2));
    }

    public function testCompleteBeforeCancellation(): void
    {
        $deferreds = \array_map(function (int $value) {
            $deferred = new DeferredFuture;
            EventLoop::delay($value / 10, fn () => $deferred->complete($value));
            return $deferred;
        }, \range(1, 3));

        self::assertSame([1, 2, 3], await(\array_map(
            fn (DeferredFuture $deferred) => $deferred->getFuture(),
            $deferreds
        ), new TimeoutCancellation(0.5)));
    }
}
